WARNING: Inconsistent field count: line 1 has 24 fields, line 2 has 33 fields
WARNING: Inconsistent field count: line 1 has 24 fields, line 3 has 33 fields
WARNING: Inconsistent field count: line 1 has 24 fields, line 4 has 33 fields
WARNING: Inconsistent field count: line 1 has 24 fields, line 5 has 33 fields
WARNING: Inconsistent field count: line 1 has 24 fields, line 6 has 33 fields
INFO: Inferring schema from CSV file: /var/folders/kv/jvn7c01n6vn6r32rdsw6yc7c0000gp/T/tmpvd68vkak/Pipe_Detail_Static_Clean.csv
✓ Schema inferred successfully
INFO: Connecting to Trino at sep.sdp-dev.pd.switchnet.nv:443
✓ Connected to Trino
INFO: Connecting to Hive metastore at localhost:9083
✓ Connected to Hive metastore
INFO: Creating table iceberg.ingestor2.pipeline_detail_005
ERROR: Error during conversion: Failed to create table: Failed to execute query: TrinoUserError(type=USER_ERROR, name=SYNTAX_ERROR, message="line 3:190: mismatched input 'TIMESTAMP'. Expecting: ')', ','", query_id=20250423_050252_31739_uvvzu)
Traceback (most recent call last):
  File "/Users/bhuey/Work/csv2iceberg/trino_client.py", line 147, in execute_query
    cursor.execute(query)
  File "/Users/bhuey/Work/csv2iceberg/lib/python3.9/site-packages/trino/dbapi.py", line 614, in execute
    self._iterator = iter(self._query.execute())
  File "/Users/bhuey/Work/csv2iceberg/lib/python3.9/site-packages/trino/client.py", line 900, in execute
    self._result.rows += self.fetch()
  File "/Users/bhuey/Work/csv2iceberg/lib/python3.9/site-packages/trino/client.py", line 920, in fetch
    status = self._request.process(response)
  File "/Users/bhuey/Work/csv2iceberg/lib/python3.9/site-packages/trino/client.py", line 689, in process
    raise self._process_error(response["error"], response.get("id"))
trino.exceptions.TrinoUserError: TrinoUserError(type=USER_ERROR, name=SYNTAX_ERROR, message="line 3:190: mismatched input 'TIMESTAMP'. Expecting: ')', ','", query_id=20250423_050252_31739_uvvzu)

During handling of the above exception, another exception occurred:

Traceback (most recent call last):
  File "/Users/bhuey/Work/csv2iceberg/trino_client.py", line 241, in create_iceberg_table
    self.execute_query(create_table_sql)
  File "/Users/bhuey/Work/csv2iceberg/trino_client.py", line 161, in execute_query
    raise RuntimeError(f"Failed to execute query: {str(e)}")
RuntimeError: Failed to execute query: TrinoUserError(type=USER_ERROR, name=SYNTAX_ERROR, message="line 3:190: mismatched input 'TIMESTAMP'. Expecting: ')', ','", query_id=20250423_050252_31739_uvvzu)

During handling of the above exception, another exception occurred:

Traceback (most recent call last):
  File "/Users/bhuey/Work/csv2iceberg/csv_to_iceberg.py", line 132, in convert
    trino_client.create_iceberg_table(catalog, schema, table, iceberg_schema)
  File "/Users/bhuey/Work/csv2iceberg/trino_client.py", line 245, in create_iceberg_table
    raise RuntimeError(f"Failed to create table: {str(e)}")
RuntimeError: Failed to create table: Failed to execute query: TrinoUserError(type=USER_ERROR, name=SYNTAX_ERROR, message="line 3:190: mismatched input 'TIMESTAMP'. Expecting: ')', ','", query_id=20250423_050252_31739_uvvzu)
Error: Failed to create table: Failed to execute query: 
TrinoUserError(type=USER_ERROR, name=SYNTAX_ERROR, message="line 3:190: 
mismatched input 'TIMESTAMP'. Expecting: ')', ','", 
query_id=20250423_050252_31739_uvvzu)