Error executing query: TrinoUserError(type=USER_ERROR, name=TYPE_MISMATCH, message="Insert query has mismatched column types: Table: [varchar, varchar, varchar, varchar, varchar, varchar, varchar, varchar, double, double, timestamp(6), timestamp(6), varchar, varchar, double, double, varchar, varchar, varchar, varchar, double, varchar, varchar, varchar], Query: [varchar, varchar, varchar, varchar, varchar, varchar, varchar, varchar, varchar, varchar, varchar, varchar, varchar, varchar, varchar, varchar, varchar, varchar, varchar, varchar, varchar, varchar, varchar, varchar]", query_id=20250423_055142_36807_uvvzu)
Traceback (most recent call last):
  File "/Users/bhuey/Work/csv2iceberg/trino_client.py", line 147, in execute_query
    cursor.execute(query)
  File "/Users/bhuey/Work/csv2iceberg/lib/python3.9/site-packages/trino/dbapi.py", line 614, in execute
    self._iterator = iter(self._query.execute())
  File "/Users/bhuey/Work/csv2iceberg/lib/python3.9/site-packages/trino/client.py", line 900, in execute
    self._result.rows += self.fetch()
  File "/Users/bhuey/Work/csv2iceberg/lib/python3.9/site-packages/trino/client.py", line 920, in fetch
    status = self._request.process(response)
  File "/Users/bhuey/Work/csv2iceberg/lib/python3.9/site-packages/trino/client.py", line 689, in process
    raise self._process_error(response["error"], response.get("id"))
trino.exceptions.TrinoUserError: TrinoUserError(type=USER_ERROR, name=TYPE_MISMATCH, message="Insert query has mismatched column types: Table: [varchar, varchar, varchar, varchar, varchar, varchar, varchar, varchar, double, double, timestamp(6), timestamp(6), varchar, varchar, double, double, varchar, varchar, varchar, varchar, double, varchar, varchar, varchar], Query: [varchar, varchar, varchar, varchar, varchar, varchar, varchar, varchar, varchar, varchar, varchar, varchar, varchar, varchar, varchar, varchar, varchar, varchar, varchar, varchar, varchar, varchar, varchar, varchar]", query_id=20250423_055142_36807_uvvzu)
PyArrow/PyIceberg direct write failed: Failed to execute query: TrinoUserError(type=USER_ERROR, name=TYPE_MISMATCH, message="Insert query has mismatched column types: Table: [varchar, varchar, varchar, varchar, varchar, varchar, varchar, varchar, double, double, timestamp(6), timestamp(6), varchar, varchar, double, double, varchar, varchar, varchar, varchar, double, varchar, varchar, varchar], Query: [varchar, varchar, varchar, varchar, varchar, varchar, varchar, varchar, varchar, varchar, varchar, varchar, varchar, varchar, varchar, varchar, varchar, varchar, varchar, varchar, varchar, varchar, varchar, varchar]", query_id=20250423_055142_36807_uvvzu), falling back to SQL INSERT
/Users/bhuey/Work/csv2iceberg/lib/python3.9/site-packages/urllib3/connectionpool.py:1013: InsecureRequestWarning: Unverified HTTPS request is being made to host 'sep.sdp-dev.pd.switchnet.nv'. Adding certificate verification is strongly advised. See: https://urllib3.readthedocs.io/en/1.26.x/advanced-usage.html#ssl-warnings
  warnings.warn(
/Users/bhuey/Work/csv2iceberg/lib/python3.9/site-packages/urllib3/connectionpool.py:1013: InsecureRequestWarning: Unverified HTTPS request is being made to host 'sep.sdp-dev.pd.switchnet.nv'. Adding certificate verification is strongly advised. See: https://urllib3.readthedocs.io/en/1.26.x/advanced-usage.html#ssl-warnings
  warnings.warn(
/Users/bhuey/Work/csv2iceberg/lib/python3.9/site-packages/urllib3/connectionpool.py:1013: InsecureRequestWarning: Unverified HTTPS request is being made to host 'sep.sdp-dev.pd.switchnet.nv'. Adding certificate verification is strongly advised. See: https://urllib3.readthedocs.io/en/1.26.x/advanced-usage.html#ssl-warnings
  warnings.warn(
/Users/bhuey/Work/csv2iceberg/lib/python3.9/site-packages/urllib3/connectionpool.py:1013: InsecureRequestWarning: Unverified HTTPS request is being made to host 'sep.sdp-dev.pd.switchnet.nv'. Adding certificate verification is strongly advised. See: https://urllib3.readthedocs.io/en/1.26.x/advanced-usage.html#ssl-warnings
  warnings.warn(
/Users/bhuey/Work/csv2iceberg/lib/python3.9/site-packages/urllib3/connectionpool.py:1013: InsecureRequestWarning: Unverified HTTPS request is being made to host 'sep.sdp-dev.pd.switchnet.nv'. Adding certificate verification is strongly advised. See: https://urllib3.readthedocs.io/en/1.26.x/advanced-usage.html#ssl-warnings
  warnings.warn(
/Users/bhuey/Work/csv2iceberg/lib/python3.9/site-packages/urllib3/connectionpool.py:1013: InsecureRequestWarning: Unverified HTTPS request is being made to host 'sep.sdp-dev.pd.switchnet.nv'. Adding certificate verification is strongly advised. See: https://urllib3.readthedocs.io/en/1.26.x/advanced-usage.html#ssl-warnings
  warnings.warn(
/Users/bhuey/Work/csv2iceberg/lib/python3.9/site-packages/urllib3/connectionpool.py:1013: InsecureRequestWarning: Unverified HTTPS request is being made to host 'sep.sdp-dev.pd.switchnet.nv'. Adding certificate verification is strongly advised. See: https://urllib3.readthedocs.io/en/1.26.x/advanced-usage.html#ssl-warnings
  warnings.warn(
/Users/bhuey/Work/csv2iceberg/lib/python3.9/site-packages/urllib3/connectionpool.py:1013: InsecureRequestWarning: Unverified HTTPS request is being made to host 'sep.sdp-dev.pd.switchnet.nv'. Adding certificate verification is strongly advised. See: https://urllib3.readthedocs.io/en/1.26.x/advanced-usage.html#ssl-warnings
  warnings.warn(
Error executing query: TrinoUserError(type=USER_ERROR, name=TYPE_MISMATCH, message="Insert query has mismatched column types: Table: [varchar, varchar, varchar, varchar, varchar, varchar, varchar, varchar, double, double, timestamp(6), timestamp(6), varchar, varchar, double, double, varchar, varchar, varchar, varchar, double, varchar, varchar, varchar], Query: [varchar(18), varchar(27), varchar(8), varchar(60), varchar(120), varchar(15), varchar(7), varchar(10), varchar(4), varchar(4), varchar(8), varchar(8), varchar(171), varchar(255), varchar(6), varchar(6), varchar(20), varchar(17), varchar(10), varchar(7), varchar(4), varchar(14), varchar(16), varchar(15)]", query_id=20250423_055143_36809_uvvzu)
Traceback (most recent call last):
  File "/Users/bhuey/Work/csv2iceberg/trino_client.py", line 147, in execute_query
    cursor.execute(query)
  File "/Users/bhuey/Work/csv2iceberg/lib/python3.9/site-packages/trino/dbapi.py", line 614, in execute
    self._iterator = iter(self._query.execute())
  File "/Users/bhuey/Work/csv2iceberg/lib/python3.9/site-packages/trino/client.py", line 900, in execute
    self._result.rows += self.fetch()
  File "/Users/bhuey/Work/csv2iceberg/lib/python3.9/site-packages/trino/client.py", line 920, in fetch
    status = self._request.process(response)
  File "/Users/bhuey/Work/csv2iceberg/lib/python3.9/site-packages/trino/client.py", line 689, in process
    raise self._process_error(response["error"], response.get("id"))
trino.exceptions.TrinoUserError: TrinoUserError(type=USER_ERROR, name=TYPE_MISMATCH, message="Insert query has mismatched column types: Table: [varchar, varchar, varchar, varchar, varchar, varchar, varchar, varchar, double, double, timestamp(6), timestamp(6), varchar, varchar, double, double, varchar, varchar, varchar, varchar, double, varchar, varchar, varchar], Query: [varchar, varchar, varchar, varchar, varchar, varchar, varchar, varchar, varchar, varchar, varchar, varchar, varchar, varchar, varchar, varchar, varchar, varchar, varchar, varchar, varchar, varchar, varchar, varchar]", query_id=20250423_055142_36807_uvvzu)

During handling of the above exception, another exception occurred:

Traceback (most recent call last):
  File "/Users/bhuey/Work/csv2iceberg/iceberg_writer.py", line 325, in _write_batch_to_iceberg
    self.trino_client.execute_query(insert_final_sql)
  File "/Users/bhuey/Work/csv2iceberg/trino_client.py", line 161, in execute_query
    raise RuntimeError(f"Failed to execute query: {str(e)}")
RuntimeError: Failed to execute query: TrinoUserError(type=USER_ERROR, name=TYPE_MISMATCH, message="Insert query has mismatched column types: Table: [varchar, varchar, varchar, varchar, varchar, varchar, varchar, varchar, double, double, timestamp(6), timestamp(6), varchar, varchar, double, double, varchar, varchar, varchar, varchar, double, varchar, varchar, varchar], Query: [varchar, varchar, varchar, varchar, varchar, varchar, varchar, varchar, varchar, varchar, varchar, varchar, varchar, varchar, varchar, varchar, varchar, varchar, varchar, varchar, varchar, varchar, varchar, varchar]", query_id=20250423_055142_36807_uvvzu)

During handling of the above exception, another exception occurred:

Traceback (most recent call last):
  File "/Users/bhuey/Work/csv2iceberg/trino_client.py", line 147, in execute_query
    cursor.execute(query)
  File "/Users/bhuey/Work/csv2iceberg/lib/python3.9/site-packages/trino/dbapi.py", line 614, in execute
    self._iterator = iter(self._query.execute())
  File "/Users/bhuey/Work/csv2iceberg/lib/python3.9/site-packages/trino/client.py", line 900, in execute
    self._result.rows += self.fetch()
  File "/Users/bhuey/Work/csv2iceberg/lib/python3.9/site-packages/trino/client.py", line 920, in fetch
    status = self._request.process(response)
  File "/Users/bhuey/Work/csv2iceberg/lib/python3.9/site-packages/trino/client.py", line 689, in process
    raise self._process_error(response["error"], response.get("id"))
trino.exceptions.TrinoUserError: TrinoUserError(type=USER_ERROR, name=TYPE_MISMATCH, message="Insert query has mismatched column types: Table: [varchar, varchar, varchar, varchar, varchar, varchar, varchar, varchar, double, double, timestamp(6), timestamp(6), varchar, varchar, double, double, varchar, varchar, varchar, varchar, double, varchar, varchar, varchar], Query: [varchar(18), varchar(27), varchar(8), varchar(60), varchar(120), varchar(15), varchar(7), varchar(10), varchar(4), varchar(4), varchar(8), varchar(8), varchar(171), varchar(255), varchar(6), varchar(6), varchar(20), varchar(17), varchar(10), varchar(7), varchar(4), varchar(14), varchar(16), varchar(15)]", query_id=20250423_055143_36809_uvvzu)
Error in _write_batch_to_iceberg: Failed to execute query: TrinoUserError(type=USER_ERROR, name=TYPE_MISMATCH, message="Insert query has mismatched column types: Table: [varchar, varchar, varchar, varchar, varchar, varchar, varchar, varchar, double, double, timestamp(6), timestamp(6), varchar, varchar, double, double, varchar, varchar, varchar, varchar, double, varchar, varchar, varchar], Query: [varchar(18), varchar(27), varchar(8), varchar(60), varchar(120), varchar(15), varchar(7), varchar(10), varchar(4), varchar(4), varchar(8), varchar(8), varchar(171), varchar(255), varchar(6), varchar(6), varchar(20), varchar(17), varchar(10), varchar(7), varchar(4), varchar(14), varchar(16), varchar(15)]", query_id=20250423_055143_36809_uvvzu)
Traceback (most recent call last):
  File "/Users/bhuey/Work/csv2iceberg/trino_client.py", line 147, in execute_query
    cursor.execute(query)
  File "/Users/bhuey/Work/csv2iceberg/lib/python3.9/site-packages/trino/dbapi.py", line 614, in execute
    self._iterator = iter(self._query.execute())
  File "/Users/bhuey/Work/csv2iceberg/lib/python3.9/site-packages/trino/client.py", line 900, in execute
    self._result.rows += self.fetch()
  File "/Users/bhuey/Work/csv2iceberg/lib/python3.9/site-packages/trino/client.py", line 920, in fetch
    status = self._request.process(response)
  File "/Users/bhuey/Work/csv2iceberg/lib/python3.9/site-packages/trino/client.py", line 689, in process
    raise self._process_error(response["error"], response.get("id"))
trino.exceptions.TrinoUserError: TrinoUserError(type=USER_ERROR, name=TYPE_MISMATCH, message="Insert query has mismatched column types: Table: [varchar, varchar, varchar, varchar, varchar, varchar, varchar, varchar, double, double, timestamp(6), timestamp(6), varchar, varchar, double, double, varchar, varchar, varchar, varchar, double, varchar, varchar, varchar], Query: [varchar, varchar, varchar, varchar, varchar, varchar, varchar, varchar, varchar, varchar, varchar, varchar, varchar, varchar, varchar, varchar, varchar, varchar, varchar, varchar, varchar, varchar, varchar, varchar]", query_id=20250423_055142_36807_uvvzu)

During handling of the above exception, another exception occurred:

Traceback (most recent call last):
  File "/Users/bhuey/Work/csv2iceberg/iceberg_writer.py", line 325, in _write_batch_to_iceberg
    self.trino_client.execute_query(insert_final_sql)
  File "/Users/bhuey/Work/csv2iceberg/trino_client.py", line 161, in execute_query
    raise RuntimeError(f"Failed to execute query: {str(e)}")
RuntimeError: Failed to execute query: TrinoUserError(type=USER_ERROR, name=TYPE_MISMATCH, message="Insert query has mismatched column types: Table: [varchar, varchar, varchar, varchar, varchar, varchar, varchar, varchar, double, double, timestamp(6), timestamp(6), varchar, varchar, double, double, varchar, varchar, varchar, varchar, double, varchar, varchar, varchar], Query: [varchar, varchar, varchar, varchar, varchar, varchar, varchar, varchar, varchar, varchar, varchar, varchar, varchar, varchar, varchar, varchar, varchar, varchar, varchar, varchar, varchar, varchar, varchar, varchar]", query_id=20250423_055142_36807_uvvzu)

During handling of the above exception, another exception occurred:

Traceback (most recent call last):
  File "/Users/bhuey/Work/csv2iceberg/trino_client.py", line 147, in execute_query
    cursor.execute(query)
  File "/Users/bhuey/Work/csv2iceberg/lib/python3.9/site-packages/trino/dbapi.py", line 614, in execute
    self._iterator = iter(self._query.execute())
  File "/Users/bhuey/Work/csv2iceberg/lib/python3.9/site-packages/trino/client.py", line 900, in execute
    self._result.rows += self.fetch()
  File "/Users/bhuey/Work/csv2iceberg/lib/python3.9/site-packages/trino/client.py", line 920, in fetch
    status = self._request.process(response)
  File "/Users/bhuey/Work/csv2iceberg/lib/python3.9/site-packages/trino/client.py", line 689, in process
    raise self._process_error(response["error"], response.get("id"))
trino.exceptions.TrinoUserError: TrinoUserError(type=USER_ERROR, name=TYPE_MISMATCH, message="Insert query has mismatched column types: Table: [varchar, varchar, varchar, varchar, varchar, varchar, varchar, varchar, double, double, timestamp(6), timestamp(6), varchar, varchar, double, double, varchar, varchar, varchar, varchar, double, varchar, varchar, varchar], Query: [varchar(18), varchar(27), varchar(8), varchar(60), varchar(120), varchar(15), varchar(7), varchar(10), varchar(4), varchar(4), varchar(8), varchar(8), varchar(171), varchar(255), varchar(6), varchar(6), varchar(20), varchar(17), varchar(10), varchar(7), varchar(4), varchar(14), varchar(16), varchar(15)]", query_id=20250423_055143_36809_uvvzu)

During handling of the above exception, another exception occurred:

Traceback (most recent call last):
  File "/Users/bhuey/Work/csv2iceberg/iceberg_writer.py", line 423, in _write_batch_to_iceberg
    self.trino_client.execute_query(insert_sql)
  File "/Users/bhuey/Work/csv2iceberg/trino_client.py", line 161, in execute_query
    raise RuntimeError(f"Failed to execute query: {str(e)}")
RuntimeError: Failed to execute query: TrinoUserError(type=USER_ERROR, name=TYPE_MISMATCH, message="Insert query has mismatched column types: Table: [varchar, varchar, varchar, varchar, varchar, varchar, varchar, varchar, double, double, timestamp(6), timestamp(6), varchar, varchar, double, double, varchar, varchar, varchar, varchar, double, varchar, varchar, varchar], Query: [varchar(18), varchar(27), varchar(8), varchar(60), varchar(120), varchar(15), varchar(7), varchar(10), varchar(4), varchar(4), varchar(8), varchar(8), varchar(171), varchar(255), varchar(6), varchar(6), varchar(20), varchar(17), varchar(10), varchar(7), varchar(4), varchar(14), varchar(16), varchar(15)]", query_id=20250423_055143_36809_uvvzu)
Error writing CSV to Iceberg: Failed to write batch to Iceberg: Failed to execute query: TrinoUserError(type=USER_ERROR, name=TYPE_MISMATCH, message="Insert query has mismatched column types: Table: [varchar, varchar, varchar, varchar, varchar, varchar, varchar, varchar, double, double, timestamp(6), timestamp(6), varchar, varchar, double, double, varchar, varchar, varchar, varchar, double, varchar, varchar, varchar], Query: [varchar(18), varchar(27), varchar(8), varchar(60), varchar(120), varchar(15), varchar(7), varchar(10), varchar(4), varchar(4), varchar(8), varchar(8), varchar(171), varchar(255), varchar(6), varchar(6), varchar(20), varchar(17), varchar(10), varchar(7), varchar(4), varchar(14), varchar(16), varchar(15)]", query_id=20250423_055143_36809_uvvzu)
Traceback (most recent call last):
  File "/Users/bhuey/Work/csv2iceberg/trino_client.py", line 147, in execute_query
    cursor.execute(query)
  File "/Users/bhuey/Work/csv2iceberg/lib/python3.9/site-packages/trino/dbapi.py", line 614, in execute
    self._iterator = iter(self._query.execute())
  File "/Users/bhuey/Work/csv2iceberg/lib/python3.9/site-packages/trino/client.py", line 900, in execute
    self._result.rows += self.fetch()
  File "/Users/bhuey/Work/csv2iceberg/lib/python3.9/site-packages/trino/client.py", line 920, in fetch
    status = self._request.process(response)
  File "/Users/bhuey/Work/csv2iceberg/lib/python3.9/site-packages/trino/client.py", line 689, in process
    raise self._process_error(response["error"], response.get("id"))
trino.exceptions.TrinoUserError: TrinoUserError(type=USER_ERROR, name=TYPE_MISMATCH, message="Insert query has mismatched column types: Table: [varchar, varchar, varchar, varchar, varchar, varchar, varchar, varchar, double, double, timestamp(6), timestamp(6), varchar, varchar, double, double, varchar, varchar, varchar, varchar, double, varchar, varchar, varchar], Query: [varchar, varchar, varchar, varchar, varchar, varchar, varchar, varchar, varchar, varchar, varchar, varchar, varchar, varchar, varchar, varchar, varchar, varchar, varchar, varchar, varchar, varchar, varchar, varchar]", query_id=20250423_055142_36807_uvvzu)

During handling of the above exception, another exception occurred:

Traceback (most recent call last):
  File "/Users/bhuey/Work/csv2iceberg/iceberg_writer.py", line 325, in _write_batch_to_iceberg
    self.trino_client.execute_query(insert_final_sql)
  File "/Users/bhuey/Work/csv2iceberg/trino_client.py", line 161, in execute_query
    raise RuntimeError(f"Failed to execute query: {str(e)}")
RuntimeError: Failed to execute query: TrinoUserError(type=USER_ERROR, name=TYPE_MISMATCH, message="Insert query has mismatched column types: Table: [varchar, varchar, varchar, varchar, varchar, varchar, varchar, varchar, double, double, timestamp(6), timestamp(6), varchar, varchar, double, double, varchar, varchar, varchar, varchar, double, varchar, varchar, varchar], Query: [varchar, varchar, varchar, varchar, varchar, varchar, varchar, varchar, varchar, varchar, varchar, varchar, varchar, varchar, varchar, varchar, varchar, varchar, varchar, varchar, varchar, varchar, varchar, varchar]", query_id=20250423_055142_36807_uvvzu)

During handling of the above exception, another exception occurred:

Traceback (most recent call last):
  File "/Users/bhuey/Work/csv2iceberg/trino_client.py", line 147, in execute_query
    cursor.execute(query)
  File "/Users/bhuey/Work/csv2iceberg/lib/python3.9/site-packages/trino/dbapi.py", line 614, in execute
    self._iterator = iter(self._query.execute())
  File "/Users/bhuey/Work/csv2iceberg/lib/python3.9/site-packages/trino/client.py", line 900, in execute
    self._result.rows += self.fetch()
  File "/Users/bhuey/Work/csv2iceberg/lib/python3.9/site-packages/trino/client.py", line 920, in fetch
    status = self._request.process(response)
  File "/Users/bhuey/Work/csv2iceberg/lib/python3.9/site-packages/trino/client.py", line 689, in process
    raise self._process_error(response["error"], response.get("id"))
trino.exceptions.TrinoUserError: TrinoUserError(type=USER_ERROR, name=TYPE_MISMATCH, message="Insert query has mismatched column types: Table: [varchar, varchar, varchar, varchar, varchar, varchar, varchar, varchar, double, double, timestamp(6), timestamp(6), varchar, varchar, double, double, varchar, varchar, varchar, varchar, double, varchar, varchar, varchar], Query: [varchar(18), varchar(27), varchar(8), varchar(60), varchar(120), varchar(15), varchar(7), varchar(10), varchar(4), varchar(4), varchar(8), varchar(8), varchar(171), varchar(255), varchar(6), varchar(6), varchar(20), varchar(17), varchar(10), varchar(7), varchar(4), varchar(14), varchar(16), varchar(15)]", query_id=20250423_055143_36809_uvvzu)

During handling of the above exception, another exception occurred:

Traceback (most recent call last):
  File "/Users/bhuey/Work/csv2iceberg/iceberg_writer.py", line 423, in _write_batch_to_iceberg
    self.trino_client.execute_query(insert_sql)
  File "/Users/bhuey/Work/csv2iceberg/trino_client.py", line 161, in execute_query
    raise RuntimeError(f"Failed to execute query: {str(e)}")
RuntimeError: Failed to execute query: TrinoUserError(type=USER_ERROR, name=TYPE_MISMATCH, message="Insert query has mismatched column types: Table: [varchar, varchar, varchar, varchar, varchar, varchar, varchar, varchar, double, double, timestamp(6), timestamp(6), varchar, varchar, double, double, varchar, varchar, varchar, varchar, double, varchar, varchar, varchar], Query: [varchar(18), varchar(27), varchar(8), varchar(60), varchar(120), varchar(15), varchar(7), varchar(10), varchar(4), varchar(4), varchar(8), varchar(8), varchar(171), varchar(255), varchar(6), varchar(6), varchar(20), varchar(17), varchar(10), varchar(7), varchar(4), varchar(14), varchar(16), varchar(15)]", query_id=20250423_055143_36809_uvvzu)

During handling of the above exception, another exception occurred:

Traceback (most recent call last):
  File "/Users/bhuey/Work/csv2iceberg/iceberg_writer.py", line 105, in write_csv_to_iceberg
    self._write_batch_to_iceberg(chunk, current_mode)
  File "/Users/bhuey/Work/csv2iceberg/iceberg_writer.py", line 429, in _write_batch_to_iceberg
    raise RuntimeError(f"Failed to write batch to Iceberg: {str(e)}")
RuntimeError: Failed to write batch to Iceberg: Failed to execute query: TrinoUserError(type=USER_ERROR, name=TYPE_MISMATCH, message="Insert query has mismatched column types: Table: [varchar, varchar, varchar, varchar, varchar, varchar, varchar, varchar, double, double, timestamp(6), timestamp(6), varchar, varchar, double, double, varchar, varchar, varchar, varchar, double, varchar, varchar, varchar], Query: [varchar(18), varchar(27), varchar(8), varchar(60), varchar(120), varchar(15), varchar(7), varchar(10), varchar(4), varchar(4), varchar(8), varchar(8), varchar(171), varchar(255), varchar(6), varchar(6), varchar(20), varchar(17), varchar(10), varchar(7), varchar(4), varchar(14), varchar(16), varchar(15)]", query_id=20250423_055143_36809_uvvzu)