Error executing query: TrinoUserError(type=USER_ERROR, name=DUPLICATE_COLUMN_NAME, message="line 3:56: Column name 'column2' specified more than once", query_id=20250423_054637_36381_uvvzu)
Traceback (most recent call last):
  File "/Users/bhuey/Work/csv2iceberg/iceberg_writer.py", line 297, in _write_batch_to_iceberg
    elif isinstance(val, (datetime.date, datetime.datetime)):
AttributeError: type object 'datetime.datetime' has no attribute 'datetime'

During handling of the above exception, another exception occurred:

Traceback (most recent call last):
  File "/Users/bhuey/Work/csv2iceberg/trino_client.py", line 147, in execute_query
    cursor.execute(query)
  File "/Users/bhuey/Work/csv2iceberg/lib/python3.9/site-packages/trino/dbapi.py", line 614, in execute
    self._iterator = iter(self._query.execute())
  File "/Users/bhuey/Work/csv2iceberg/lib/python3.9/site-packages/trino/client.py", line 900, in execute
    self._result.rows += self.fetch()
  File "/Users/bhuey/Work/csv2iceberg/lib/python3.9/site-packages/trino/client.py", line 920, in fetch
    status = self._request.process(response)
  File "/Users/bhuey/Work/csv2iceberg/lib/python3.9/site-packages/trino/client.py", line 689, in process
    raise self._process_error(response["error"], response.get("id"))
trino.exceptions.TrinoUserError: TrinoUserError(type=USER_ERROR, name=DUPLICATE_COLUMN_NAME, message="line 3:56: Column name 'column2' specified more than once", query_id=20250423_054637_36381_uvvzu)
Error in _write_batch_to_iceberg: Failed to execute query: TrinoUserError(type=USER_ERROR, name=DUPLICATE_COLUMN_NAME, message="line 3:56: Column name 'column2' specified more than once", query_id=20250423_054637_36381_uvvzu)
Traceback (most recent call last):
  File "/Users/bhuey/Work/csv2iceberg/iceberg_writer.py", line 297, in _write_batch_to_iceberg
    elif isinstance(val, (datetime.date, datetime.datetime)):
AttributeError: type object 'datetime.datetime' has no attribute 'datetime'

During handling of the above exception, another exception occurred:

Traceback (most recent call last):
  File "/Users/bhuey/Work/csv2iceberg/trino_client.py", line 147, in execute_query
    cursor.execute(query)
  File "/Users/bhuey/Work/csv2iceberg/lib/python3.9/site-packages/trino/dbapi.py", line 614, in execute
    self._iterator = iter(self._query.execute())
  File "/Users/bhuey/Work/csv2iceberg/lib/python3.9/site-packages/trino/client.py", line 900, in execute
    self._result.rows += self.fetch()
  File "/Users/bhuey/Work/csv2iceberg/lib/python3.9/site-packages/trino/client.py", line 920, in fetch
    status = self._request.process(response)
  File "/Users/bhuey/Work/csv2iceberg/lib/python3.9/site-packages/trino/client.py", line 689, in process
    raise self._process_error(response["error"], response.get("id"))
trino.exceptions.TrinoUserError: TrinoUserError(type=USER_ERROR, name=DUPLICATE_COLUMN_NAME, message="line 3:56: Column name 'column2' specified more than once", query_id=20250423_054637_36381_uvvzu)

During handling of the above exception, another exception occurred:

Traceback (most recent call last):
  File "/Users/bhuey/Work/csv2iceberg/iceberg_writer.py", line 410, in _write_batch_to_iceberg
    self.trino_client.execute_query(insert_sql)
  File "/Users/bhuey/Work/csv2iceberg/trino_client.py", line 161, in execute_query
    raise RuntimeError(f"Failed to execute query: {str(e)}")
RuntimeError: Failed to execute query: TrinoUserError(type=USER_ERROR, name=DUPLICATE_COLUMN_NAME, message="line 3:56: Column name 'column2' specified more than once", query_id=20250423_054637_36381_uvvzu)
Error writing CSV to Iceberg: Failed to write batch to Iceberg: Failed to execute query: TrinoUserError(type=USER_ERROR, name=DUPLICATE_COLUMN_NAME, message="line 3:56: Column name 'column2' specified more than once", query_id=20250423_054637_36381_uvvzu)
Traceback (most recent call last):
  File "/Users/bhuey/Work/csv2iceberg/iceberg_writer.py", line 297, in _write_batch_to_iceberg
    elif isinstance(val, (datetime.date, datetime.datetime)):
AttributeError: type object 'datetime.datetime' has no attribute 'datetime'

During handling of the above exception, another exception occurred:

Traceback (most recent call last):
  File "/Users/bhuey/Work/csv2iceberg/trino_client.py", line 147, in execute_query
    cursor.execute(query)
  File "/Users/bhuey/Work/csv2iceberg/lib/python3.9/site-packages/trino/dbapi.py", line 614, in execute
    self._iterator = iter(self._query.execute())
  File "/Users/bhuey/Work/csv2iceberg/lib/python3.9/site-packages/trino/client.py", line 900, in execute
    self._result.rows += self.fetch()
  File "/Users/bhuey/Work/csv2iceberg/lib/python3.9/site-packages/trino/client.py", line 920, in fetch
    status = self._request.process(response)
  File "/Users/bhuey/Work/csv2iceberg/lib/python3.9/site-packages/trino/client.py", line 689, in process
    raise self._process_error(response["error"], response.get("id"))
trino.exceptions.TrinoUserError: TrinoUserError(type=USER_ERROR, name=DUPLICATE_COLUMN_NAME, message="line 3:56: Column name 'column2' specified more than once", query_id=20250423_054637_36381_uvvzu)

During handling of the above exception, another exception occurred:

Traceback (most recent call last):
  File "/Users/bhuey/Work/csv2iceberg/iceberg_writer.py", line 410, in _write_batch_to_iceberg
    self.trino_client.execute_query(insert_sql)
  File "/Users/bhuey/Work/csv2iceberg/trino_client.py", line 161, in execute_query
    raise RuntimeError(f"Failed to execute query: {str(e)}")
RuntimeError: Failed to execute query: TrinoUserError(type=USER_ERROR, name=DUPLICATE_COLUMN_NAME, message="line 3:56: Column name 'column2' specified more than once", query_id=20250423_054637_36381_uvvzu)

During handling of the above exception, another exception occurred:

Traceback (most recent call last):
  File "/Users/bhuey/Work/csv2iceberg/iceberg_writer.py", line 105, in write_csv_to_iceberg
    self._write_batch_to_iceberg(chunk, current_mode)
  File "/Users/bhuey/Work/csv2iceberg/iceberg_writer.py", line 416, in _write_batch_to_iceberg
    raise RuntimeError(f"Failed to write batch to Iceberg: {str(e)}")
RuntimeError: Failed to write batch to Iceberg: Failed to execute query: TrinoUserError(type=USER_ERROR, name=DUPLICATE_COLUMN_NAME, message="line 3:56: Column name 'column2' specified more than once", query_id=20250423_054637_36381_uvvzu)