Traceback (most recent call last):
  File "/usr/src/app/feature-branches/refactor/csv2iceberg/csv_to_iceberg/core/iceberg_writer.py", line 591, in _write_batch_to_iceberg
    self.trino_client.execute_query(direct_insert_sql)
  File "/usr/src/app/feature-branches/refactor/csv2iceberg/csv_to_iceberg/connectors/trino_client.py", line 170, in execute_query
    raise RuntimeError(f"Failed to execute query: {str(e)}")
RuntimeError: Failed to execute query: TrinoUserError(type=USER_ERROR, name=COLUMN_NOT_FOUND, message="Insert column name does not exist in target table: close date", query_id=20250424_211223_44455_uvvzu)
INFO:csv_to_iceberg.core.iceberg_writer:Invalidating schema cache due to error in overwrite mode
INFO:csv_to_iceberg.core.iceberg_writer:Invalidating schema cache for iceberg.ingestor2.refactor_test_005
ERROR:csv_to_iceberg.core.iceberg_writer:Error writing CSV to Iceberg: Failed to write batch to Iceberg: Failed to execute query: TrinoUserError(type=USER_ERROR, name=COLUMN_NOT_FOUND, message="Insert column name does not exist in target table: close date", query_id=20250424_211223_44455_uvvzu)
Traceback (most recent call last):
  File "/usr/src/app/feature-branches/refactor/csv2iceberg/csv_to_iceberg/connectors/trino_client.py", line 156, in execute_query
    cursor.execute(query)
  File "/usr/src/app/feature-branches/refactor/csv2iceberg/lib/python3.12/site-packages/trino/dbapi.py", line 614, in execute
    self._iterator = iter(self._query.execute())
                          ^^^^^^^^^^^^^^^^^^^^^
  File "/usr/src/app/feature-branches/refactor/csv2iceberg/lib/python3.12/site-packages/trino/client.py", line 900, in execute
    self._result.rows += self.fetch()
                         ^^^^^^^^^^^^
  File "/usr/src/app/feature-branches/refactor/csv2iceberg/lib/python3.12/site-packages/trino/client.py", line 920, in fetch
    status = self._request.process(response)
             ^^^^^^^^^^^^^^^^^^^^^^^^^^^^^^^
  File "/usr/src/app/feature-branches/refactor/csv2iceberg/lib/python3.12/site-packages/trino/client.py", line 689, in process
    raise self._process_error(response["error"], response.get("id"))
trino.exceptions.TrinoUserError: TrinoUserError(type=USER_ERROR, name=COLUMN_NOT_FOUND, message="Insert column name does not exist in target table: close date", query_id=20250424_211223_44455_uvvzu)

During handling of the above exception, another exception occurred:

Traceback (most recent call last):
  File "/usr/src/app/feature-branches/refactor/csv2iceberg/csv_to_iceberg/core/iceberg_writer.py", line 591, in _write_batch_to_iceberg
    self.trino_client.execute_query(direct_insert_sql)
  File "/usr/src/app/feature-branches/refactor/csv2iceberg/csv_to_iceberg/connectors/trino_client.py", line 170, in execute_query
    raise RuntimeError(f"Failed to execute query: {str(e)}")
RuntimeError: Failed to execute query: TrinoUserError(type=USER_ERROR, name=COLUMN_NOT_FOUND, message="Insert column name does not exist in target table: close date", query_id=20250424_211223_44455_uvvzu)

During handling of the above exception, another exception occurred:

Traceback (most recent call last):
  File "/usr/src/app/feature-branches/refactor/csv2iceberg/csv_to_iceberg/core/iceberg_writer.py", line 169, in write_csv_to_iceberg
    self._write_batch_to_iceberg(batch, current_mode)
  File "/usr/src/app/feature-branches/refactor/csv2iceberg/csv_to_iceberg/core/iceberg_writer.py", line 620, in _write_batch_to_iceberg
    raise RuntimeError(f"Failed to write batch to Iceberg: {str(e)}")
RuntimeError: Failed to write batch to Iceberg: Failed to execute query: TrinoUserError(type=USER_ERROR, name=COLUMN_NOT_FOUND, message="Insert column name does not exist in target table: close date", query_id=20250424_211223_44455_uvvzu)
ERROR:csv_to_iceberg.core.conversion_service:Error during conversion: Failed to write CSV to Iceberg: Failed to write batch to Iceberg: Failed to execute query: TrinoUserError(type=USER_ERROR, name=COLUMN_NOT_FOUND, message="Insert column name does not exist in target table: close date", query_id=20250424_211223_44455_uvvzu)
Traceback (most recent call last):
  File "/usr/src/app/feature-branches/refactor/csv2iceberg/csv_to_iceberg/connectors/trino_client.py", line 156, in execute_query
    cursor.execute(query)
  File "/usr/src/app/feature-branches/refactor/csv2iceberg/lib/python3.12/site-packages/trino/dbapi.py", line 614, in execute
    self._iterator = iter(self._query.execute())
                          ^^^^^^^^^^^^^^^^^^^^^
  File "/usr/src/app/feature-branches/refactor/csv2iceberg/lib/python3.12/site-packages/trino/client.py", line 900, in execute
    self._result.rows += self.fetch()
                         ^^^^^^^^^^^^
  File "/usr/src/app/feature-branches/refactor/csv2iceberg/lib/python3.12/site-packages/trino/client.py", line 920, in fetch
    status = self._request.process(response)
             ^^^^^^^^^^^^^^^^^^^^^^^^^^^^^^^
  File "/usr/src/app/feature-branches/refactor/csv2iceberg/lib/python3.12/site-packages/trino/client.py", line 689, in process
    raise self._process_error(response["error"], response.get("id"))
trino.exceptions.TrinoUserError: TrinoUserError(type=USER_ERROR, name=COLUMN_NOT_FOUND, message="Insert column name does not exist in target table: close date", query_id=20250424_211223_44455_uvvzu)

During handling of the above exception, another exception occurred:

Traceback (most recent call last):
  File "/usr/src/app/feature-branches/refactor/csv2iceberg/csv_to_iceberg/core/iceberg_writer.py", line 591, in _write_batch_to_iceberg
    self.trino_client.execute_query(direct_insert_sql)
  File "/usr/src/app/feature-branches/refactor/csv2iceberg/csv_to_iceberg/connectors/trino_client.py", line 170, in execute_query
    raise RuntimeError(f"Failed to execute query: {str(e)}")
RuntimeError: Failed to execute query: TrinoUserError(type=USER_ERROR, name=COLUMN_NOT_FOUND, message="Insert column name does not exist in target table: close date", query_id=20250424_211223_44455_uvvzu)

During handling of the above exception, another exception occurred:

Traceback (most recent call last):
  File "/usr/src/app/feature-branches/refactor/csv2iceberg/csv_to_iceberg/core/iceberg_writer.py", line 169, in write_csv_to_iceberg
    self._write_batch_to_iceberg(batch, current_mode)
  File "/usr/src/app/feature-branches/refactor/csv2iceberg/csv_to_iceberg/core/iceberg_writer.py", line 620, in _write_batch_to_iceberg
    raise RuntimeError(f"Failed to write batch to Iceberg: {str(e)}")
RuntimeError: Failed to write batch to Iceberg: Failed to execute query: TrinoUserError(type=USER_ERROR, name=COLUMN_NOT_FOUND, message="Insert column name does not exist in target table: close date", query_id=20250424_211223_44455_uvvzu)

During handling of the above exception, another exception occurred:

Traceback (most recent call last):
  File "/usr/src/app/feature-branches/refactor/csv2iceberg/csv_to_iceberg/core/conversion_service.py", line 130, in convert_csv_to_iceberg
    rows_written = writer.write_csv_to_iceberg(
                   ^^^^^^^^^^^^^^^^^^^^^^^^^^^^
  File "/usr/src/app/feature-branches/refactor/csv2iceberg/csv_to_iceberg/core/iceberg_writer.py", line 190, in write_csv_to_iceberg
    raise RuntimeError(f"Failed to write CSV to Iceberg: {str(e)}")
RuntimeError: Failed to write CSV to Iceberg: Failed to write batch to Iceberg: Failed to execute query: TrinoUserError(type=USER_ERROR, name=COLUMN_NOT_FOUND, message="Insert column name does not exist in target table: close date", query_id=20250424_211223_44455_uvvzu)
